try {
    throw(CustomException);
} catch (CustomException) {
    prints("Caught custom exception");
}