try {
    throw(CustomException);
} catch (CustomException) {
    printe("Caught custom exception");
}